#VRML_SIM R2022a utf8
WorldInfo {
}
Viewpoint {
  fieldOfView 1.0472
  orientation 0.31788190441929526 -0.010004433246593001 -0.9480775317231057 3.1835087364415515
  position 2.844336351998166 0.7996407403526403 2.359561596027475
}
Solid {
  rotation 1 0 0 0
  children [
    Shape {
      appearance PBRAppearance {
        baseColor 0.45 0.15 0.15
        roughness 1
        metalness 0
        IBLStrength 0
        emissiveIntensity 0
      }
      geometry Plane {
        size 8 8
      }
    }
  ]
  name "Floor"
  boundingObject Plane {
    size 8 8
  }
  locked TRUE
}
Background {
  skyColor [
    0.15 0.45 1
  ]
}
DirectionalLight {
  castShadows TRUE
}
DEF RobotTemplate Robot {
  translation 1.8087759141732468e-10 1.0986102185610335e-07 -0.001363378486078759
  rotation 0.9999996046133542 -1.0545962728517921e-05 0.0008891917215829847 0.0003998599798733738
  children [
    Transform {
      translation 0 0 1.04
      children [
        HingeJoint {
          jointParameters HingeJointParameters {
          }
          device [
            RotationalMotor {
            }
          ]
          endPoint Solid {
            translation 0 0 0.15
            rotation 1 0 0 0
            children [
              Shape {
                appearance Appearance {
                  material Material {
                  }
                }
                geometry Box {
                  size 0.1 0.1 0.3
                }
              }
            ]
          }
        }
      ]
    }
    DEF s_front_left SwerveWheel {
      translation 0.37 -0.35 0.07
      wheelDevice [
        PositionSensor {
          name "CAN1 #"
        }
        RotationalMotor {
          name "Motor1 # front left wheel"
        }
      ]
      steeringDevice [
        PositionSensor {
          name "CAN11 #"
        }
        RotationalMotor {
          name "Motor11 # front left direction"
        }
      ]
    }
    DEF s_front_right SwerveWheel {
      translation -0.37 -0.35 0.07
      name "wheel(1)"
      wheelDevice [
        PositionSensor {
          name "CAN2 #"
        }
        RotationalMotor {
          name "Motor2 # front right wheel"
        }
      ]
      steeringDevice [
        PositionSensor {
          name "CAN12 #"
        }
        RotationalMotor {
          name "Motor12 # front right direction"
        }
      ]
    }
    DEF s_back_left SwerveWheel {
      translation 0.37 0.35 0.07
      name "wheel(2)"
      wheelDevice [
        PositionSensor {
          name "CAN3 #"
        }
        RotationalMotor {
          name "Motor3 # back left wheel"
        }
      ]
      steeringDevice [
        PositionSensor {
          name "CAN13 #"
        }
        RotationalMotor {
          name "Motor13 # back left direction"
        }
      ]
    }
    DEF s_back_right SwerveWheel {
      translation -0.37 0.35 0.07
      name "wheel(3)"
      wheelDevice [
        PositionSensor {
          name "CAN4 #"
        }
        RotationalMotor {
          name "Motor4 # back right wheel"
        }
      ]
      steeringDevice [
        PositionSensor {
          name "CAN14 #"
        }
        RotationalMotor {
          name "Motor14 # back right direction"
        }
      ]
    }
    Gyro {
      translation 0 0 0.2
      name "Gyro1"
    }
    Camera {
      translation 0 0.4953 0.5
      rotation 1.8366025517039032e-06 -1.836602551703903e-06 0.9999999999966269 1.5707963267982696
      children [
        Transform {
          rotation 0.5773502691896258 -0.5773502691896258 -0.5773502691896258 2.0943951023931953
          children [
            Shape {
              appearance PBRAppearance {
                baseColor 0 0 0
              }
              geometry Box {
                size 0.02 0.02 0.02
              }
            }
          ]
        }
      ]
      width 848
      height 800
      lens Lens {
        radialCoefficients -0.5 0
      }
    }
    InertialUnit {
      name "IMU1"
    }
    Transform {
      translation 0 0 0.2
      children [
        Shape {
          appearance PBRAppearance {
            metalness 0
          }
          geometry Box {
            size 0.9 1.1 0.1
          }
        }
      ]
    }
  ]
  name "basic robot"
  boundingObject Transform {
    translation 0 0 0.5
    scale 1.25 1.15 1
    children [
      Shape {
        appearance PBRAppearance {
          metalness 0
        }
        geometry Box {
          size 0.7112 0.9652 0.7
        }
      }
    ]
  }
  physics Physics {
    density -1
    mass 25
    centerOfMass [
      0 0 0.2
    ]
  }
  supervisor TRUE
  synchronization FALSE
  linearVelocity 4.261458274472847e-11 -5.4236154758573626e-05 -5.074501240022297e-05
  angularVelocity 0.000286195351541186 2.2464770771890838e-10 1.9425695460554475e-12
}
B99_Furniture_Sofa_Ottoman {
  translation 6.453801544552309e-14 3.00000000000934 -0.001098720014592297
  rotation -9.145609347564182e-12 2.448679382827877e-12 1 0.523599
}
Checkerboard {
  translation 0.114 1.03 0.395
  rotation 0 0 1 3.14159
}
