#VRML_SIM R2022a utf8
WorldInfo {
}
Viewpoint {
  orientation 0.1956279012394106 -0.13128447600440096 -0.9718508685065386 4.673044330790547
  position 0.0830428235226671 -1.045103460726444 0.3881515676653977
}
RectangleArena {
}
Robot {
  translation 0.0003506932144585575 3.0370626764904768e-09 0.04935981792808598
  rotation -8.665838361742588e-06 0.9999999999624329 1.9266212888857525e-07 0.007013901925056331
  children [
    Transform {
      translation 0 0 0.05
      children [
        DEF body Shape {
          appearance Appearance {
          }
          geometry Box {
            size 0.1 0.1 0.1
          }
        }
        Transform {
          translation -0.13 0 0
          children [
            Hinge2Joint {
              jointParameters HingeJointParameters {
                axis 0 0 1
              }
              jointParameters2 JointParameters {
                axis 1 0 0
              }
              device [
                RotationalMotor {
                  name "direction_motor"
                }
              ]
              device2 [
                RotationalMotor {
                  name "wheel_motor"
                }
              ]
              endPoint RobotWheel {
                rotation 0 1 0 -1.5707953071795862
              }
            }
          ]
        }
      ]
    }
  ]
  contactMaterial "body"
  boundingObject Transform {
    translation 0 0 0.05
    children [
      USE body
    ]
  }
  physics Physics {
    mass 0.5
  }
  controller "my_controller"
}
TexturedBackground {
  texture "empty_office"
}
TexturedBackgroundLight {
  texture "dusk"
}
