#VRML_SIM R2022a utf8

PROTO SwerveWheel [
  field SFVec3f    translation 0 0 0
  field SFRotation rotation    0 1 0 1.5708
  field SFString   name        "wheel"
  field SFFloat    height      0.0254
  field SFFloat    radius      0.0762
  field MFNode {RotationalMotor{}, PositionSensor{}, Brake{}}     wheelDevice      NULL
  field MFNode {RotationalMotor{}, PositionSensor{}, Brake{}}     directionDevice      NULL
  field SFNode     physics     Physics {
  }
]
{
    Hinge2Joint {
      jointParameters HingeJointParameters {
        position 0
        anchor IS translation
      }
      jointParameters2 JointParameters {
        position 0
      }
      device IS directionDevice
      device2 IS wheelDevice
      endPoint RobotWheel {
        translation IS translation
        rotation IS rotation
        name IS name
        physics IS physics
        height IS height
        radius IS radius
      }
    }
}